Workbook

Sheet Tổng hợp
G1: TRONG GÓI KHÁM | AF1: DỊCH VỤ ĐĂNG KÝ THÊM
A2: STT HỆ THỐNG | B2: Họ và tên | C2: Ngày sinh | D2: Giới tính | E2: Phòng ban | F2: Chức vụ | G2: Khám Da Liễu-Khám Sức Khỏe (TT32_BYT) | H2: Khám Mắt-Khám Sức Khỏe (TT32_BYT) | I2: Khám Nội-Khám Sức Khỏe (TT32_BYT) | J2: Khám Ngoại-Khám Sức Khỏe (TT32_BYT) | K2: Khám RHM-Khám Sức Khỏe (TT32_BYT) | L2: Khám SPK-Khám Sức Khỏe (TT32_BYT) | M2: Khám vú | N2: Khám TMH-Khám Sức Khỏe (TT32_BYT) | O2: Tổng Kết Hồ Sơ Khám Sức Khỏe (TT32_BYT) | P2: NƯỚC TIỂU 10 THÔNG SỐ (KSK) | Q2: Chụp X-quang tim phổi kỹ thuật số (hãng Fuji-Nhật) | R2: Điện tâm đồ/ECG | S2: Siêu âm màu Bụng Tổng Quát (Máy GE LOGIQ S7 Expert) | T2: Siêu âm màu Tuyến Giáp | U2: ALT (SGPT) | V2: AST (SGOT) | W2: Test ma túy tổng hợp (lái xe) | X2: Tổng phân tích tế bào máu bằng máy laser | Y2: Cholesterol TP | Z2: Triglyceride | AA2: Định lượng ACID URIC máu | AB2: Định lượng CREATINIE máu | AC2: Định lượng GLUCOSE máu | AD2: Ethanol (Nồng độ cồn trong máu) | AE2: Chụp CT Scanner Ngực | AF2: Nội soi họng - thanh quản | AG2: Nội soi Tai Mũi Họng | AH2: Calci toàn phần | AI2: Định lượng Ca++ máu (Calci ion hoá) | AJ2: Chẩn đoán tế bào học (vị trí 1) | AK2: Chọc hút tế bào bằng kim nhỏ dưới siêu âm | AL2: Chọc hút tế bào bằng kim nhỏ dưới siêu âm (FNA) (vị trí 1) - Trọn gói | AM2: Soi tươi (Soi trực tiếp nhuộm gram) : Dịch âm đạo | AN2: Lấy cao răng độ 2,3/ Lần | AO2: CHI PHÍ TRONG GÓI | AP2: CHI PHÍ PHÁT SINH | AQ2: NOTE
G3: 20000 | H3: 20000 | I3: 50000 | J3: 20000 | K3: 20000 | L3: Ưu đãi trong gói | M3: Ưu đãi trong gói | N3: 20000 | O3: Ưu đãi trong gói | P3: 59000 | Q3: 102000 | R3: 70000 | S3: 155000 | T3: 155000 | U3: 30000 | V3: 30000 | W3: 183000 | X3: 75000 | Y3: 47000 | Z3: 41000 | AA3: 41000 | AB3: 41000 | AC3: 27000 | AD3: 233000 | AE3: 630000 | AF3: 198000 | AG3: 241200 | AH3: 18000 | AI3: 27000 | AJ3: 422100 | AM3: 64800 | AN3: 225000
A4: =_xlfn.XLOOKUP(B4,[1]DS!$B$2:$B$40,[1]DS!$A$2:$A$40) -> 1 | B4: Nguyễn Trọng Cường | C4: 1971 | D4: Nam | E4: =_xlfn.XLOOKUP(B4,[1]DS!$B$2:$B$40,[1]DS!$F$2:$F$40) -> Lãnh đạo | F4: =_xlfn.XLOOKUP(B4,[1]DS!$B$2:$B$40,[1]DS!$G$2:$G$40) -> Giám đốc | G4: X | H4: X | I4: X | J4: X | K4: X | N4: X | O4: X | P4: X | Q4: X | R4: X | S4: X | T4: X | U4: X | V4: X | X4: X | Y4: X | Z4: X | AA4: X | AB4: X | AC4: X | AE4: X | AG4: X | AO4: =SUMIF(G4:AD4,"X",$G$3:$AD$3) -> 1023000 | AP4: =SUMIF(AE4:AN4,"X",$AE$3:$AN$3) -> 871200
A5: =_xlfn.XLOOKUP(B5,[1]DS!$B$2:$B$40,[1]DS!$A$2:$A$40) -> 2 | B5: Trương Văn Cường | C5: 1983 | D5: Nam | E5: =_xlfn.XLOOKUP(B5,[1]DS!$B$2:$B$40,[1]DS!$F$2:$F$40) -> Lãnh đạo | F5: =_xlfn.XLOOKUP(B5,[1]DS!$B$2:$B$40,[1]DS!$G$2:$G$40) -> Phó giám đốc | G5: X | H5: X | I5: X | J5: X | K5: X | N5: X | O5: X | P5: X | Q5: X | R5: X | S5: X | T5: X | U5: X | V5: X | X5: X | Y5: X | Z5: X | AA5: X | AB5: X | AC5: X | AO5: =SUMIF(G5:AD5,"X",$G$3:$AD$3) -> 1023000 | AP5: =SUMIF(AE5:AN5,"X",$AE$3:$AN$3) -> 0
A6: =_xlfn.XLOOKUP(B6,[1]DS!$B$2:$B$40,[1]DS!$A$2:$A$40) -> 3 | B6: Nguyễn Kim Trọng | C6: 1972 | D6: Nam | E6: =_xlfn.XLOOKUP(B6,[1]DS!$B$2:$B$40,[1]DS!$F$2:$F$40) -> Phòng Hành chính-Tổng hợp | F6: =_xlfn.XLOOKUP(B6,[1]DS!$B$2:$B$40,[1]DS!$G$2:$G$40) -> Trưởng phòng | G6: X | H6: X | I6: X | J6: X | K6: X | N6: X | O6: X | P6: X | Q6: X | R6: X | S6: X | T6: X | U6: X | V6: X | X6: X | Y6: X | Z6: X | AA6: X | AB6: X | AC6: X | AO6: =SUMIF(G6:AD6,"X",$G$3:$AD$3) -> 1023000 | AP6: =SUMIF(AE6:AN6,"X",$AE$3:$AN$3) -> 0
A7: =_xlfn.XLOOKUP(B7,[1]DS!$B$2:$B$40,[1]DS!$A$2:$A$40) -> 4 | B7: Nguyễn Văn Thọ | C7: 1972 | D7: Nam | E7: =_xlfn.XLOOKUP(B7,[1]DS!$B$2:$B$40,[1]DS!$F$2:$F$40) -> Phòng Hành chính-Tổng hợp | F7: =_xlfn.XLOOKUP(B7,[1]DS!$B$2:$B$40,[1]DS!$G$2:$G$40) -> Nhân viên lái xe | G7: X | H7: X | I7: X | J7: X | K7: X | N7: X | O7: X | P7: X | Q7: X | R7: X | S7: X | T7: X | U7: X | V7: X | W7: X | X7: X | Y7: X | Z7: X | AA7: X | AB7: X | AC7: X | AD7: X | AO7: =SUMIF(G7:AD7,"X",$G$3:$AD$3) -> 1439000 | AP7: =SUMIF(AE7:AN7,"X",$AE$3:$AN$3) -> 0
A8: =_xlfn.XLOOKUP(B8,[1]DS!$B$2:$B$40,[1]DS!$A$2:$A$40) -> 5 | B8: Trịnh Minh Thắng | C8: 30/08/1975 | D8: Nam | E8: =_xlfn.XLOOKUP(B8,[1]DS!$B$2:$B$40,[1]DS!$F$2:$F$40) -> Phòng Kế hoạch | F8: =_xlfn.XLOOKUP(B8,[1]DS!$B$2:$B$40,[1]DS!$G$2:$G$40) -> Trưởng phòng | G8: X | H8: X | I8: X | J8: X | K8: X | N8: X | O8: X | P8: X | Q8: X | R8: X | S8: X | T8: X | U8: X | V8: X | X8: X | Y8: X | Z8: X | AA8: X | AB8: X | AC8: X | AO8: =SUMIF(G8:AD8,"X",$G$3:$AD$3) -> 1023000 | AP8: =SUMIF(AE8:AN8,"X",$AE$3:$AN$3) -> 0
A9: =_xlfn.XLOOKUP(B9,[1]DS!$B$2:$B$40,[1]DS!$A$2:$A$40) -> 6 | B9: Dương Dũng | C9: 1968 | D9: Nam | E9: =_xlfn.XLOOKUP(B9,[1]DS!$B$2:$B$40,[1]DS!$F$2:$F$40) -> Phòng Kế hoạch | F9: =_xlfn.XLOOKUP(B9,[1]DS!$B$2:$B$40,[1]DS!$G$2:$G$40) -> Chuyên viên | G9: X | H9: X | I9: X | J9: X | K9: X | N9: X | O9: X | P9: X | Q9: X | R9: X | S9: X | T9: X | U9: X | V9: X | X9: X | Y9: X | Z9: X | AA9: X | AB9: X | AC9: X | AO9: =SUMIF(G9:AD9,"X",$G$3:$AD$3) -> 1023000 | AP9: =SUMIF(AE9:AN9,"X",$AE$3:$AN$3) -> 0
A10: =_xlfn.XLOOKUP(B10,[1]DS!$B$2:$B$40,[1]DS!$A$2:$A$40) -> 7 | B10: Phan Lê Phước Nghĩa | C10: 1979 | D10: Nam | E10: =_xlfn.XLOOKUP(B10,[1]DS!$B$2:$B$40,[1]DS!$F$2:$F$40) -> Phòng Kế hoạch | F10: =_xlfn.XLOOKUP(B10,[1]DS!$B$2:$B$40,[1]DS!$G$2:$G$40) -> Chuyên viên | G10: X | H10: X | I10: X | J10: X | K10: X | N10: X | O10: X | P10: X | Q10: X | R10: X | S10: X | T10: X | U10: X | V10: X | X10: X | Y10: X | Z10: X | AA10: X | AB10: X | AC10: X | AO10: =SUMIF(G10:AD10,"X",$G$3:$AD$3) -> 1023000 | AP10: =SUMIF(AE10:AN10,"X",$AE$3:$AN$3) -> 0
A11: =_xlfn.XLOOKUP(B11,[1]DS!$B$2:$B$40,[1]DS!$A$2:$A$40) -> 8 | B11: Bùi Tấn Sơn | C11: 1995 | D11: Nam | E11: =_xlfn.XLOOKUP(B11,[1]DS!$B$2:$B$40,[1]DS!$F$2:$F$40) -> Phòng Kế hoạch | F11: =_xlfn.XLOOKUP(B11,[1]DS!$B$2:$B$40,[1]DS!$G$2:$G$40) -> Chuyên viên | G11: X | H11: X | I11: X | J11: X | K11: X | N11: X | O11: X | P11: X | Q11: X | R11: X | S11: X | T11: X | U11: X | V11: X | X11: X | Y11: X | Z11: X | AA11: X | AB11: X | AC11: X | AO11: =SUMIF(G11:AD11,"X",$G$3:$AD$3) -> 1023000 | AP11: =SUMIF(AE11:AN11,"X",$AE$3:$AN$3) -> 0
A12: =_xlfn.XLOOKUP(B12,[1]DS!$B$2:$B$40,[1]DS!$A$2:$A$40) -> 9 | B12: Ông Văn Lộc | C12: 1981 | D12: Nam | E12: =_xlfn.XLOOKUP(B12,[1]DS!$B$2:$B$40,[1]DS!$F$2:$F$40) -> Phòng Kỹ Thuật | F12: =_xlfn.XLOOKUP(B12,[1]DS!$B$2:$B$40,[1]DS!$G$2:$G$40) -> Trưởng phòng | G12: X | H12: X | I12: X | J12: X | K12: X | N12: X | O12: X | P12: X | Q12: X | R12: X | S12: X | T12: X | U12: X | V12: X | X12: X | Y12: X | Z12: X | AA12: X | AB12: X | AC12: X | AO12: =SUMIF(G12:AD12,"X",$G$3:$AD$3) -> 1023000 | AP12: =SUMIF(AE12:AN12,"X",$AE$3:$AN$3) -> 0
A13: =_xlfn.XLOOKUP(B13,[1]DS!$B$2:$B$40,[1]DS!$A$2:$A$40) -> 10 | B13: Nguyễn Huy Liêm | C13: 02/09/1985 | D13: Nam | E13: =_xlfn.XLOOKUP(B13,[1]DS!$B$2:$B$40,[1]DS!$F$2:$F$40) -> Phòng Kỹ Thuật | F13: =_xlfn.XLOOKUP(B13,[1]DS!$B$2:$B$40,[1]DS!$G$2:$G$40) -> Chuyên viên | G13: X | H13: X | I13: X | J13: X | K13: X | N13: X | O13: X | P13: X | Q13: X | R13: X | S13: X | T13: X | U13: X | V13: X | X13: X | Y13: X | Z13: X | AA13: X | AB13: X | AC13: X | AO13: =SUMIF(G13:AD13,"X",$G$3:$AD$3) -> 1023000 | AP13: =SUMIF(AE13:AN13,"X",$AE$3:$AN$3) -> 0
A14: =_xlfn.XLOOKUP(B14,[1]DS!$B$2:$B$40,[1]DS!$A$2:$A$40) -> 11 | B14: Trần Tuấn Hảo | C14: 1966 | D14: Nam | E14: =_xlfn.XLOOKUP(B14,[1]DS!$B$2:$B$40,[1]DS!$F$2:$F$40) -> Phòng Kỹ Thuật | F14: =_xlfn.XLOOKUP(B14,[1]DS!$B$2:$B$40,[1]DS!$G$2:$G$40) -> Chuyên viên | G14: X | H14: X | I14: X | J14: X | K14: X | N14: X | O14: X | P14: X | Q14: X | R14: X | S14: X | T14: X | U14: X | V14: X | X14: X | Y14: X | Z14: X | AA14: X | AB14: X | AC14: X | AO14: =SUMIF(G14:AD14,"X",$G$3:$AD$3) -> 1023000 | AP14: =SUMIF(AE14:AN14,"X",$AE$3:$AN$3) -> 0
A15: =_xlfn.XLOOKUP(B15,[1]DS!$B$2:$B$40,[1]DS!$A$2:$A$40) -> 12 | B15: Ngô Hoài Phương | C15: 1994 | D15: Nam | E15: =_xlfn.XLOOKUP(B15,[1]DS!$B$2:$B$40,[1]DS!$F$2:$F$40) -> Phòng Kỹ Thuật | F15: =_xlfn.XLOOKUP(B15,[1]DS!$B$2:$B$40,[1]DS!$G$2:$G$40) -> Chuyên viên | G15: X | H15: X | I15: X | J15: X | K15: X | N15: X | O15: X | P15: X | Q15: X | R15: X | S15: X | T15: X | U15: X | V15: X | X15: X | Y15: X | Z15: X | AA15: X | AB15: X | AC15: X | AO15: =SUMIF(G15:AD15,"X",$G$3:$AD$3) -> 1023000 | AP15: =SUMIF(AE15:AN15,"X",$AE$3:$AN$3) -> 0
A16: =_xlfn.XLOOKUP(B16,[1]DS!$B$2:$B$40,[1]DS!$A$2:$A$40) -> 13 | B16: Nguyễn Trung Hiếu | C16: 1983 | D16: Nam | E16: =_xlfn.XLOOKUP(B16,[1]DS!$B$2:$B$40,[1]DS!$F$2:$F$40) -> Phòng QL KCN DVTS Đà Nẵng | F16: =_xlfn.XLOOKUP(B16,[1]DS!$B$2:$B$40,[1]DS!$G$2:$G$40) -> Trưởng phòng | G16: X | H16: X | I16: X | J16: X | K16: X | N16: X | O16: X | P16: X | Q16: X | R16: X | S16: X | T16: X | U16: X | V16: X | X16: X | Y16: X | Z16: X | AA16: X | AB16: X | AC16: X | AO16: =SUMIF(G16:AD16,"X",$G$3:$AD$3) -> 1023000 | AP16: =SUMIF(AE16:AN16,"X",$AE$3:$AN$3) -> 0
A17: =_xlfn.XLOOKUP(B17,[1]DS!$B$2:$B$40,[1]DS!$A$2:$A$40) -> 14 | B17: Trương Văn Hùng | C17: 1993 | D17: Nam | E17: =_xlfn.XLOOKUP(B17,[1]DS!$B$2:$B$40,[1]DS!$F$2:$F$40) -> Phòng QL KCN DVTS Đà Nẵng | F17: =_xlfn.XLOOKUP(B17,[1]DS!$B$2:$B$40,[1]DS!$G$2:$G$40) -> Cán sự | G17: X | H17: X | I17: X | J17: X | K17: X | N17: X | O17: X | P17: X | Q17: X | R17: X | S17: X | T17: X | U17: X | V17: X | X17: X | Y17: X | Z17: X | AA17: X | AB17: X | AC17: X | AO17: =SUMIF(G17:AD17,"X",$G$3:$AD$3) -> 1023000 | AP17: =SUMIF(AE17:AN17,"X",$AE$3:$AN$3) -> 0
A18: =_xlfn.XLOOKUP(B18,[1]DS!$B$2:$B$40,[1]DS!$A$2:$A$40) -> 15 | B18: Đỗ Viết Tấn | C18: 1973 | D18: Nam | E18: =_xlfn.XLOOKUP(B18,[1]DS!$B$2:$B$40,[1]DS!$F$2:$F$40) -> Phòng QL KCN DVTS Đà Nẵng | F18: =_xlfn.XLOOKUP(B18,[1]DS!$B$2:$B$40,[1]DS!$G$2:$G$40) -> Nhân viên bảo vệ | G18: X | H18: X | I18: X | J18: X | K18: X | N18: X | O18: X | P18: X | R18: X | S18: X | T18: X | U18: X | V18: X | X18: X | Y18: X | Z18: X | AA18: X | AB18: X | AC18: X | AO18: =SUMIF(G18:AD18,"X",$G$3:$AD$3) -> 921000 | AP18: =SUMIF(AE18:AN18,"X",$AE$3:$AN$3) -> 0 | AQ18: KHÔNG CHỤP X-QUANG
A19: =_xlfn.XLOOKUP(B19,[1]DS!$B$2:$B$40,[1]DS!$A$2:$A$40) -> 16 | B19: Phan Trung Tiến | C19: 1973 | D19: Nam | E19: =_xlfn.XLOOKUP(B19,[1]DS!$B$2:$B$40,[1]DS!$F$2:$F$40) -> Phòng QL KCN DVTS Đà Nẵng | F19: =_xlfn.XLOOKUP(B19,[1]DS!$B$2:$B$40,[1]DS!$G$2:$G$40) -> Nhân viên bảo vệ | G19: X | H19: X | I19: X | J19: X | K19: X | N19: X | O19: X | P19: X | Q19: X | R19: X | S19: X | T19: X | U19: X | V19: X | X19: X | Y19: X | Z19: X | AA19: X | AB19: X | AC19: X | AO19: =SUMIF(G19:AD19,"X",$G$3:$AD$3) -> 1023000 | AP19: =SUMIF(AE19:AN19,"X",$AE$3:$AN$3) -> 0
A20: =_xlfn.XLOOKUP(B20,[1]DS!$B$2:$B$40,[1]DS!$A$2:$A$40) -> 17 | B20: Lê Trung Hiếu | C20: 2001 | D20: Nam | E20: =_xlfn.XLOOKUP(B20,[1]DS!$B$2:$B$40,[1]DS!$F$2:$F$40) -> Phòng QL KCN DVTS Đà Nẵng | F20: =_xlfn.XLOOKUP(B20,[1]DS!$B$2:$B$40,[1]DS!$G$2:$G$40) -> Nhân viên bảo vệ | G20: X | H20: X | I20: X | J20: X | K20: X | N20: X | O20: X | P20: X | Q20: X | R20: X | S20: X | T20: X | U20: X | V20: X | X20: X | Y20: X | Z20: X | AA20: X | AB20: X | AC20: X | AO20: =SUMIF(G20:AD20,"X",$G$3:$AD$3) -> 1023000 | AP20: =SUMIF(AE20:AN20,"X",$AE$3:$AN$3) -> 0
A21: =_xlfn.XLOOKUP(B21,[1]DS!$B$2:$B$40,[1]DS!$A$2:$A$40) -> 18 | B21: Văn Quang Viên | C21: 1979 | D21: Nam | E21: =_xlfn.XLOOKUP(B21,[1]DS!$B$2:$B$40,[1]DS!$F$2:$F$40) -> Xí nghiệp QL&DV KCN Hòa Khánh | F21: =_xlfn.XLOOKUP(B21,[1]DS!$B$2:$B$40,[1]DS!$G$2:$G$40) -> Giám đốc XN | G21: X | H21: X | I21: X | J21: X | K21: X | N21: X | O21: X | P21: X | Q21: X | R21: X | S21: X | T21: X | U21: X | V21: X | X21: X | Y21: X | Z21: X | AA21: X | AB21: X | AC21: X | AN21: X | AO21: =SUMIF(G21:AD21,"X",$G$3:$AD$3) -> 1023000 | AP21: =SUMIF(AE21:AN21,"X",$AE$3:$AN$3) -> 225000
A22: =_xlfn.XLOOKUP(B22,[1]DS!$B$2:$B$40,[1]DS!$A$2:$A$40) -> 19 | B22: Ngô Tấn Trung | C22: 01/09/1977 | D22: Nam | E22: =_xlfn.XLOOKUP(B22,[1]DS!$B$2:$B$40,[1]DS!$F$2:$F$40) -> Xí nghiệp QL&DV KCN Hòa Khánh | F22: =_xlfn.XLOOKUP(B22,[1]DS!$B$2:$B$40,[1]DS!$G$2:$G$40) -> Phó giám đốc XN | G22: X | H22: X | I22: X | J22: X | K22: X | N22: X | O22: X | P22: X | Q22: X | R22: X | S22: X | T22: X | U22: X | V22: X | X22: X | Y22: X | Z22: X | AA22: X | AB22: X | AC22: X | AO22: =SUMIF(G22:AD22,"X",$G$3:$AD$3) -> 1023000 | AP22: =SUMIF(AE22:AN22,"X",$AE$3:$AN$3) -> 0
A23: =_xlfn.XLOOKUP(B23,[1]DS!$B$2:$B$40,[1]DS!$A$2:$A$40) -> 20 | B23: Nguyễn Pho | C23: 1977 | D23: Nam | E23: =_xlfn.XLOOKUP(B23,[1]DS!$B$2:$B$40,[1]DS!$F$2:$F$40) -> Xí nghiệp QL&DV KCN Hòa Khánh | F23: =_xlfn.XLOOKUP(B23,[1]DS!$B$2:$B$40,[1]DS!$G$2:$G$40) -> Phó giám đốc XN | G23: X | H23: X | I23: X | J23: X | K23: X | N23: X | O23: X | P23: X | Q23: X | R23: X | S23: X | T23: X | U23: X | V23: X | X23: X | Y23: X | Z23: X | AA23: X | AB23: X | AC23: X | AO23: =SUMIF(G23:AD23,"X",$G$3:$AD$3) -> 1023000 | AP23: =SUMIF(AE23:AN23,"X",$AE$3:$AN$3) -> 0
A24: =_xlfn.XLOOKUP(B24,[1]DS!$B$2:$B$40,[1]DS!$A$2:$A$40) -> 21 | B24: Phan Văn Hùng | C24: 1972 | D24: Nam | E24: =_xlfn.XLOOKUP(B24,[1]DS!$B$2:$B$40,[1]DS!$F$2:$F$40) -> Xí nghiệp QL&DV KCN Hòa Khánh | F24: =_xlfn.XLOOKUP(B24,[1]DS!$B$2:$B$40,[1]DS!$G$2:$G$40) -> Cán sự | G24: X | H24: X | I24: X | J24: X | K24: X | N24: X | O24: X | P24: X | Q24: X | R24: X | S24: X | T24: X | U24: X | V24: X | X24: X | Y24: X | Z24: X | AA24: X | AB24: X | AC24: X | AO24: =SUMIF(G24:AD24,"X",$G$3:$AD$3) -> 1023000 | AP24: =SUMIF(AE24:AN24,"X",$AE$3:$AN$3) -> 0
A25: =_xlfn.XLOOKUP(B25,[1]DS!$B$2:$B$40,[1]DS!$A$2:$A$40) -> 22 | B25: Trần Văn Quân | C25: 1971 | D25: Nam | E25: =_xlfn.XLOOKUP(B25,[1]DS!$B$2:$B$40,[1]DS!$F$2:$F$40) -> Xí nghiệp QL&DV KCN Hòa Khánh | F25: =_xlfn.XLOOKUP(B25,[1]DS!$B$2:$B$40,[1]DS!$G$2:$G$40) -> Nhân viên bảo vệ | G25: X | H25: X | I25: X | J25: X | K25: X | N25: X | O25: X | P25: X | Q25: X | R25: X | S25: X | T25: X | U25: X | V25: X | X25: X | Y25: X | Z25: X | AA25: X | AB25: X | AC25: X | AO25: =SUMIF(G25:AD25,"X",$G$3:$AD$3) -> 1023000 | AP25: =SUMIF(AE25:AN25,"X",$AE$3:$AN$3) -> 0
A26: =_xlfn.XLOOKUP(B26,[1]DS!$B$2:$B$40,[1]DS!$A$2:$A$40) -> 23 | B26: Phan Xuân Khánh | C26: 1968 | D26: Nam | E26: =_xlfn.XLOOKUP(B26,[1]DS!$B$2:$B$40,[1]DS!$F$2:$F$40) -> Xí nghiệp QL&DV KCN Hòa Khánh | F26: =_xlfn.XLOOKUP(B26,[1]DS!$B$2:$B$40,[1]DS!$G$2:$G$40) -> Nhân viên lái xe | G26: X | H26: X | I26: X | J26: X | K26: X | N26: X | O26: X | P26: X | Q26: X | R26: X | S26: X | T26: X | U26: X | V26: X | W26: X | X26: X | Y26: X | Z26: X | AA26: X | AB26: X | AC26: X | AD26: X | AF26: X | AO26: =SUMIF(G26:AD26,"X",$G$3:$AD$3) -> 1439000 | AP26: =SUMIF(AE26:AN26,"X",$AE$3:$AN$3) -> 198000
A27: =_xlfn.XLOOKUP(B27,[1]DS!$B$2:$B$40,[1]DS!$A$2:$A$40) -> 24 | B27: Trương Công Tuấn | C27: 24/06/1993 | D27: Nam | E27: =_xlfn.XLOOKUP(B27,[1]DS!$B$2:$B$40,[1]DS!$F$2:$F$40) -> Xí nghiệp QL&DV KCN Hòa Khánh | F27: =_xlfn.XLOOKUP(B27,[1]DS!$B$2:$B$40,[1]DS!$G$2:$G$40) -> Nhân viên lái xe | G27: X | H27: X | I27: X | J27: X | K27: X | N27: X | O27: X | P27: X | Q27: X | R27: X | S27: X | T27: X | U27: X | V27: X | W27: X | X27: X | Y27: X | Z27: X | AA27: X | AB27: X | AC27: X | AD27: X | AO27: =SUMIF(G27:AD27,"X",$G$3:$AD$3) -> 1439000 | AP27: =SUMIF(AE27:AN27,"X",$AE$3:$AN$3) -> 0
A28: =_xlfn.XLOOKUP(B28,[1]DS!$B$2:$B$40,[1]DS!$A$2:$A$40) -> 25 | B28: Nguyễn Phan Thanh | C28: 1987 | D28: Nam | E28: =_xlfn.XLOOKUP(B28,[1]DS!$B$2:$B$40,[1]DS!$F$2:$F$40) -> Xí nghiệp QL&DV KCN Hòa Khánh | F28: =_xlfn.XLOOKUP(B28,[1]DS!$B$2:$B$40,[1]DS!$G$2:$G$40) -> Nhân viên bảo vệ | G28: X | H28: X | I28: X | J28: X | K28: X | N28: X | O28: X | P28: X | Q28: X | R28: X | S28: X | T28: X | U28: X | V28: X | X28: X | Y28: X | Z28: X | AA28: X | AB28: X | AC28: X | AO28: =SUMIF(G28:AD28,"X",$G$3:$AD$3) -> 1023000 | AP28: =SUMIF(AE28:AN28,"X",$AE$3:$AN$3) -> 0
A29: =_xlfn.XLOOKUP(B29,[1]DS!$B$2:$B$40,[1]DS!$A$2:$A$40) -> 26 | B29: Phan Văn Tuấn | C29: 1977 | D29: Nam | E29: =_xlfn.XLOOKUP(B29,[1]DS!$B$2:$B$40,[1]DS!$F$2:$F$40) -> Xí nghiệp QL&DV KCN Hòa Khánh | F29: =_xlfn.XLOOKUP(B29,[1]DS!$B$2:$B$40,[1]DS!$G$2:$G$40) -> Nhân viên bảo vệ | G29: X | H29: X | I29: X | J29: X | K29: X | N29: X | O29: X | P29: X | Q29: X | R29: X | S29: X | T29: X | U29: X | V29: X | X29: X | Y29: X | Z29: X | AA29: X | AB29: X | AC29: X | AO29: =SUMIF(G29:AD29,"X",$G$3:$AD$3) -> 1023000 | AP29: =SUMIF(AE29:AN29,"X",$AE$3:$AN$3) -> 0
A30: =_xlfn.XLOOKUP(B30,[1]DS!$B$2:$B$40,[1]DS!$A$2:$A$40) -> 27 | B30: Võ Tòng Vũ | C30: 1999 | D30: Nam | E30: =_xlfn.XLOOKUP(B30,[1]DS!$B$2:$B$40,[1]DS!$F$2:$F$40) -> Xí nghiệp QL&DV KCN Hòa Khánh | F30: =_xlfn.XLOOKUP(B30,[1]DS!$B$2:$B$40,[1]DS!$G$2:$G$40) -> Nhân viên bảo vệ | G30: X | H30: X | I30: X | J30: X | K30: X | N30: X | O30: X | P30: X | Q30: X | R30: X | S30: X | T30: X | U30: X | V30: X | X30: X | Y30: X | Z30: X | AA30: X | AB30: X | AC30: X | AO30: =SUMIF(G30:AD30,"X",$G$3:$AD$3) -> 1023000 | AP30: =SUMIF(AE30:AN30,"X",$AE$3:$AN$3) -> 0
A31: =_xlfn.XLOOKUP(B31,[1]DS!$B$2:$B$40,[1]DS!$A$2:$A$40) -> 28 | B31: Nguyễn Trung Kiên | C31: 2001 | D31: Nam | E31: =_xlfn.XLOOKUP(B31,[1]DS!$B$2:$B$40,[1]DS!$F$2:$F$40) -> Xí nghiệp QL&DV KCN Hòa Khánh | F31: =_xlfn.XLOOKUP(B31,[1]DS!$B$2:$B$40,[1]DS!$G$2:$G$40) -> Nhân viên bảo vệ | G31: X | H31: X | I31: X | J31: X | K31: X | N31: X | O31: X | P31: X | Q31: X | R31: X | S31: X | T31: X | U31: X | V31: X | X31: X | Y31: X | Z31: X | AA31: X | AB31: X | AC31: X | AO31: =SUMIF(G31:AD31,"X",$G$3:$AD$3) -> 1023000 | AP31: =SUMIF(AE31:AN31,"X",$AE$3:$AN$3) -> 0
A32: =_xlfn.XLOOKUP(B32,[1]DS!$B$2:$B$40,[1]DS!$A$2:$A$40) -> 29 | B32: Trần Thu Hương | C32: 1974 | D32: Nữ | E32: =_xlfn.XLOOKUP(B32,[1]DS!$B$2:$B$40,[1]DS!$F$2:$F$40) -> Lãnh đạo | F32: =_xlfn.XLOOKUP(B32,[1]DS!$B$2:$B$40,[1]DS!$G$2:$G$40) -> Phó giám đốc | G32: X | H32: X | I32: X | J32: X | K32: X | L32: X | M32: X | N32: X | O32: X | P32: X | Q32: X | R32: X | S32: X | T32: X | U32: X | V32: X | X32: X | Y32: X | Z32: X | AA32: X | AB32: X | AC32: X | AH32: X | AI32: X | AO32: =SUMIF(G32:AD32,"X",$G$3:$AD$3) -> 1023000 | AP32: =SUMIF(AE32:AN32,"X",$AE$3:$AN$3) -> 45000
A33: =_xlfn.XLOOKUP(B33,[1]DS!$B$2:$B$40,[1]DS!$A$2:$A$40) -> 30 | B33: Nguyễn Thị Thơ | C33: 30/05/1976 | D33: Nữ | E33: =_xlfn.XLOOKUP(B33,[1]DS!$B$2:$B$40,[1]DS!$F$2:$F$40) -> Phòng Hành chính-Tổng hợp | F33: =_xlfn.XLOOKUP(B33,[1]DS!$B$2:$B$40,[1]DS!$G$2:$G$40) -> Phó trưởng phòng | G33: X | H33: X | I33: X | J33: X | K33: X | L33: X | M33: X | N33: X | O33: X | P33: X | Q33: X | R33: X | S33: X | T33: X | U33: X | V33: X | X33: X | Y33: X | Z33: X | AA33: X | AB33: X | AC33: X | AO33: =SUMIF(G33:AD33,"X",$G$3:$AD$3) -> 1023000 | AP33: =SUMIF(AE33:AN33,"X",$AE$3:$AN$3) -> 0
A34: =_xlfn.XLOOKUP(B34,[1]DS!$B$2:$B$40,[1]DS!$A$2:$A$40) -> 31 | B34: Phạm Gia Hy | C34: 1996 | D34: Nữ | E34: =_xlfn.XLOOKUP(B34,[1]DS!$B$2:$B$40,[1]DS!$F$2:$F$40) -> Phòng Hành chính-Tổng hợp | F34: =_xlfn.XLOOKUP(B34,[1]DS!$B$2:$B$40,[1]DS!$G$2:$G$40) -> Văn thư viên | G34: X | H34: X | I34: X | J34: X | K34: X | L34: X | M34: X | N34: X | O34: X | P34: X | Q34: X | R34: X | S34: X | T34: X | U34: X | V34: X | X34: X | Y34: X | Z34: X | AA34: X | AB34: X | AC34: X | AO34: =SUMIF(G34:AD34,"X",$G$3:$AD$3) -> 1023000 | AP34: =SUMIF(AE34:AN34,"X",$AE$3:$AN$3) -> 0
A35: =_xlfn.XLOOKUP(B35,[1]DS!$B$2:$B$40,[1]DS!$A$2:$A$40) -> 32 | B35: Đinh Thị Kim Tâm | C35: 1988 | D35: Nữ | E35: =_xlfn.XLOOKUP(B35,[1]DS!$B$2:$B$40,[1]DS!$F$2:$F$40) -> Phòng Kế hoạch | F35: =_xlfn.XLOOKUP(B35,[1]DS!$B$2:$B$40,[1]DS!$G$2:$G$40) -> Chuyên viên | G35: X | H35: X | I35: X | J35: X | K35: X | L35: X | M35: X | N35: X | O35: X | P35: X | Q35: X | R35: X | S35: X | T35: X | U35: X | V35: X | X35: X | Y35: X | Z35: X | AA35: X | AB35: X | AC35: X | AO35: =SUMIF(G35:AD35,"X",$G$3:$AD$3) -> 1023000 | AP35: =SUMIF(AE35:AN35,"X",$AE$3:$AN$3) -> 0
A36: =_xlfn.XLOOKUP(B36,[1]DS!$B$2:$B$40,[1]DS!$A$2:$A$40) -> 33 | B36: Nguyễn Thị Hoa | C36: 1975 | D36: Nữ | E36: =_xlfn.XLOOKUP(B36,[1]DS!$B$2:$B$40,[1]DS!$F$2:$F$40) -> Phòng Kế toán - Tài vụ | F36: =_xlfn.XLOOKUP(B36,[1]DS!$B$2:$B$40,[1]DS!$G$2:$G$40) -> Trưởng phòng | G36: X | H36: X | I36: X | J36: X | K36: X | L36: X | M36: X | N36: X | O36: X | P36: X | Q36: X | R36: X | S36: X | T36: X | U36: X | V36: X | X36: X | Y36: X | Z36: X | AA36: X | AB36: X | AC36: X | AM36: X | AO36: =SUMIF(G36:AD36,"X",$G$3:$AD$3) -> 1023000 | AP36: =SUMIF(AE36:AN36,"X",$AE$3:$AN$3) -> 64800
A37: =_xlfn.XLOOKUP(B37,[1]DS!$B$2:$B$40,[1]DS!$A$2:$A$40) -> 34 | B37: Nguyễn Hạnh Thắm | C37: 1987 | D37: Nữ | E37: =_xlfn.XLOOKUP(B37,[1]DS!$B$2:$B$40,[1]DS!$F$2:$F$40) -> Phòng Kế toán - Tài vụ | F37: =_xlfn.XLOOKUP(B37,[1]DS!$B$2:$B$40,[1]DS!$G$2:$G$40) -> Phó trưởng phòng | G37: X | H37: X | I37: X | J37: X | K37: X | L37: X | M37: X | N37: X | O37: X | P37: X | Q37: X | R37: X | S37: X | T37: X | U37: X | V37: X | X37: X | Y37: X | Z37: X | AA37: X | AB37: X | AC37: X | AO37: =SUMIF(G37:AD37,"X",$G$3:$AD$3) -> 1023000 | AP37: =SUMIF(AE37:AN37,"X",$AE$3:$AN$3) -> 0
A38: =_xlfn.XLOOKUP(B38,[1]DS!$B$2:$B$40,[1]DS!$A$2:$A$40) -> 35 | B38: Nguyễn Thị Hằng Nga | C38: 1988 | D38: Nữ | E38: =_xlfn.XLOOKUP(B38,[1]DS!$B$2:$B$40,[1]DS!$F$2:$F$40) -> Phòng Kế toán - Tài vụ | F38: =_xlfn.XLOOKUP(B38,[1]DS!$B$2:$B$40,[1]DS!$G$2:$G$40) -> Chuyên viên | G38: X | H38: X | I38: X | J38: X | K38: X | L38: X | M38: X | N38: X | O38: X | P38: X | Q38: X | R38: X | S38: X | T38: X | U38: X | V38: X | X38: X | Y38: X | Z38: X | AA38: X | AB38: X | AC38: X | AO38: =SUMIF(G38:AD38,"X",$G$3:$AD$3) -> 1023000 | AP38: =SUMIF(AE38:AN38,"X",$AE$3:$AN$3) -> 0
A39: =_xlfn.XLOOKUP(B39,[1]DS!$B$2:$B$40,[1]DS!$A$2:$A$40) -> 36 | B39: Phạm Thị Cẩm Lai | C39: 06/10/1989 | D39: Nữ | E39: =_xlfn.XLOOKUP(B39,[1]DS!$B$2:$B$40,[1]DS!$F$2:$F$40) -> Phòng Kế toán - Tài vụ | F39: =_xlfn.XLOOKUP(B39,[1]DS!$B$2:$B$40,[1]DS!$G$2:$G$40) -> Chuyên viên | G39: X | H39: X | I39: X | J39: X | K39: X | L39: X | M39: X | N39: X | O39: X | P39: X | Q39: X | R39: X | S39: X | T39: X | U39: X | V39: X | X39: X | Y39: X | Z39: X | AA39: X | AB39: X | AC39: X | AJ39: X | AK39: X | AL39: X | AO39: =SUMIF(G39:AD39,"X",$G$3:$AD$3) -> 1023000 | AP39: =SUMIF(AE39:AN39,"X",$AE$3:$AN$3) -> 422100
A40: =_xlfn.XLOOKUP(B40,[1]DS!$B$2:$B$40,[1]DS!$A$2:$A$40) -> 37 | B40: Trần Thị Anh Thư | C40: 1984 | D40: Nữ | E40: =_xlfn.XLOOKUP(B40,[1]DS!$B$2:$B$40,[1]DS!$F$2:$F$40) -> Phòng Kế hoạch | F40: =_xlfn.XLOOKUP(B40,[1]DS!$B$2:$B$40,[1]DS!$G$2:$G$40) -> Phó phòng | G40: X | H40: X | I40: X | J40: X | K40: X | L40: X | M40: X | N40: X | O40: X | P40: X | R40: X | S40: X | T40: X | U40: X | V40: X | X40: X | Y40: X | Z40: X | AA40: X | AB40: X | AC40: X | AO40: =SUMIF(G40:AD40,"X",$G$3:$AD$3) -> 921000 | AP40: =SUMIF(AE40:AN40,"X",$AE$3:$AN$3) -> 0 | AQ40: KHÔNG CHỤP X-QUANG
...

Sheet Sheet1
A1: STT | B1: Họ và tên | C1: Ngày sinh | D1: Giới tính | E1: Phòng ban | F1: Chức vụ | G1: Chi phí (VND)
A2: =_xlfn.XLOOKUP(B2,[1]DS!$B$2:$B$40,[1]DS!$A$2:$A$40) -> 1 | B2: Nguyễn Trọng Cường | C2: 1971 | D2: Nam | E2: =_xlfn.XLOOKUP(B2,[1]DS!$B$2:$B$40,[1]DS!$F$2:$F$40) -> Lãnh đạo | F2: =_xlfn.XLOOKUP(B2,[1]DS!$B$2:$B$40,[1]DS!$G$2:$G$40) -> Giám đốc | G2: =_xlfn.XLOOKUP(B2,'Tổng hợp'!$B$4:$B$42,'Tổng hợp'!$AO$4:$AO$42,,0) -> 1023000
A3: =_xlfn.XLOOKUP(B3,[1]DS!$B$2:$B$40,[1]DS!$A$2:$A$40) -> 2 | B3: Trương Văn Cường | C3: 1983 | D3: Nam | E3: =_xlfn.XLOOKUP(B3,[1]DS!$B$2:$B$40,[1]DS!$F$2:$F$40) -> Lãnh đạo | F3: =_xlfn.XLOOKUP(B3,[1]DS!$B$2:$B$40,[1]DS!$G$2:$G$40) -> Phó giám đốc | G3: =_xlfn.XLOOKUP(B3,'Tổng hợp'!$B$4:$B$42,'Tổng hợp'!$AO$4:$AO$42,,0) -> 1023000
A4: =_xlfn.XLOOKUP(B4,[1]DS!$B$2:$B$40,[1]DS!$A$2:$A$40) -> 3 | B4: Nguyễn Kim Trọng | C4: 1972 | D4: Nam | E4: =_xlfn.XLOOKUP(B4,[1]DS!$B$2:$B$40,[1]DS!$F$2:$F$40) -> Phòng Hành chính-Tổng hợp | F4: =_xlfn.XLOOKUP(B4,[1]DS!$B$2:$B$40,[1]DS!$G$2:$G$40) -> Trưởng phòng | G4: =_xlfn.XLOOKUP(B4,'Tổng hợp'!$B$4:$B$42,'Tổng hợp'!$AO$4:$AO$42,,0) -> 1023000
A5: =_xlfn.XLOOKUP(B5,[1]DS!$B$2:$B$40,[1]DS!$A$2:$A$40) -> 4 | B5: Nguyễn Văn Thọ | C5: 1972 | D5: Nam | E5: =_xlfn.XLOOKUP(B5,[1]DS!$B$2:$B$40,[1]DS!$F$2:$F$40) -> Phòng Hành chính-Tổng hợp | F5: =_xlfn.XLOOKUP(B5,[1]DS!$B$2:$B$40,[1]DS!$G$2:$G$40) -> Nhân viên lái xe | G5: =_xlfn.XLOOKUP(B5,'Tổng hợp'!$B$4:$B$42,'Tổng hợp'!$AO$4:$AO$42,,0) -> 1439000 | I5: d
A6: =_xlfn.XLOOKUP(B6,[1]DS!$B$2:$B$40,[1]DS!$A$2:$A$40) -> 5 | B6: Trịnh Minh Thắng | C6: 1975 | D6: Nam | E6: =_xlfn.XLOOKUP(B6,[1]DS!$B$2:$B$40,[1]DS!$F$2:$F$40) -> Phòng Kế hoạch | F6: =_xlfn.XLOOKUP(B6,[1]DS!$B$2:$B$40,[1]DS!$G$2:$G$40) -> Trưởng phòng | G6: =_xlfn.XLOOKUP(B6,'Tổng hợp'!$B$4:$B$42,'Tổng hợp'!$AO$4:$AO$42,,0) -> 1023000
A7: =_xlfn.XLOOKUP(B7,[1]DS!$B$2:$B$40,[1]DS!$A$2:$A$40) -> 6 | B7: Dương Dũng | C7: 1968 | D7: Nam | E7: =_xlfn.XLOOKUP(B7,[1]DS!$B$2:$B$40,[1]DS!$F$2:$F$40) -> Phòng Kế hoạch | F7: =_xlfn.XLOOKUP(B7,[1]DS!$B$2:$B$40,[1]DS!$G$2:$G$40) -> Chuyên viên | G7: =_xlfn.XLOOKUP(B7,'Tổng hợp'!$B$4:$B$42,'Tổng hợp'!$AO$4:$AO$42,,0) -> 1023000
A8: =_xlfn.XLOOKUP(B8,[1]DS!$B$2:$B$40,[1]DS!$A$2:$A$40) -> 7 | B8: Phan Lê Phước Nghĩa | C8: 1979 | D8: Nam | E8: =_xlfn.XLOOKUP(B8,[1]DS!$B$2:$B$40,[1]DS!$F$2:$F$40) -> Phòng Kế hoạch | F8: =_xlfn.XLOOKUP(B8,[1]DS!$B$2:$B$40,[1]DS!$G$2:$G$40) -> Chuyên viên | G8: =_xlfn.XLOOKUP(B8,'Tổng hợp'!$B$4:$B$42,'Tổng hợp'!$AO$4:$AO$42,,0) -> 1023000
A9: =_xlfn.XLOOKUP(B9,[1]DS!$B$2:$B$40,[1]DS!$A$2:$A$40) -> 8 | B9: Bùi Tấn Sơn | C9: 1995 | D9: Nam | E9: =_xlfn.XLOOKUP(B9,[1]DS!$B$2:$B$40,[1]DS!$F$2:$F$40) -> Phòng Kế hoạch | F9: =_xlfn.XLOOKUP(B9,[1]DS!$B$2:$B$40,[1]DS!$G$2:$G$40) -> Chuyên viên | G9: =_xlfn.XLOOKUP(B9,'Tổng hợp'!$B$4:$B$42,'Tổng hợp'!$AO$4:$AO$42,,0) -> 1023000
A10: =_xlfn.XLOOKUP(B10,[1]DS!$B$2:$B$40,[1]DS!$A$2:$A$40) -> 9 | B10: Ông Văn Lộc | C10: 1981 | D10: Nam | E10: =_xlfn.XLOOKUP(B10,[1]DS!$B$2:$B$40,[1]DS!$F$2:$F$40) -> Phòng Kỹ Thuật | F10: =_xlfn.XLOOKUP(B10,[1]DS!$B$2:$B$40,[1]DS!$G$2:$G$40) -> Trưởng phòng | G10: =_xlfn.XLOOKUP(B10,'Tổng hợp'!$B$4:$B$42,'Tổng hợp'!$AO$4:$AO$42,,0) -> 1023000
A11: =_xlfn.XLOOKUP(B11,[1]DS!$B$2:$B$40,[1]DS!$A$2:$A$40) -> 10 | B11: Nguyễn Huy Liêm | C11: 1985 | D11: Nam | E11: =_xlfn.XLOOKUP(B11,[1]DS!$B$2:$B$40,[1]DS!$F$2:$F$40) -> Phòng Kỹ Thuật | F11: =_xlfn.XLOOKUP(B11,[1]DS!$B$2:$B$40,[1]DS!$G$2:$G$40) -> Chuyên viên | G11: =_xlfn.XLOOKUP(B11,'Tổng hợp'!$B$4:$B$42,'Tổng hợp'!$AO$4:$AO$42,,0) -> 1023000
A12: =_xlfn.XLOOKUP(B12,[1]DS!$B$2:$B$40,[1]DS!$A$2:$A$40) -> 11 | B12: Trần Tuấn Hảo | C12: 1966 | D12: Nam | E12: =_xlfn.XLOOKUP(B12,[1]DS!$B$2:$B$40,[1]DS!$F$2:$F$40) -> Phòng Kỹ Thuật | F12: =_xlfn.XLOOKUP(B12,[1]DS!$B$2:$B$40,[1]DS!$G$2:$G$40) -> Chuyên viên | G12: =_xlfn.XLOOKUP(B12,'Tổng hợp'!$B$4:$B$42,'Tổng hợp'!$AO$4:$AO$42,,0) -> 1023000
A13: =_xlfn.XLOOKUP(B13,[1]DS!$B$2:$B$40,[1]DS!$A$2:$A$40) -> 12 | B13: Ngô Hoài Phương | C13: 1994 | D13: Nam | E13: =_xlfn.XLOOKUP(B13,[1]DS!$B$2:$B$40,[1]DS!$F$2:$F$40) -> Phòng Kỹ Thuật | F13: =_xlfn.XLOOKUP(B13,[1]DS!$B$2:$B$40,[1]DS!$G$2:$G$40) -> Chuyên viên | G13: =_xlfn.XLOOKUP(B13,'Tổng hợp'!$B$4:$B$42,'Tổng hợp'!$AO$4:$AO$42,,0) -> 1023000
A14: =_xlfn.XLOOKUP(B14,[1]DS!$B$2:$B$40,[1]DS!$A$2:$A$40) -> 13 | B14: Nguyễn Trung Hiếu | C14: 1983 | D14: Nam | E14: =_xlfn.XLOOKUP(B14,[1]DS!$B$2:$B$40,[1]DS!$F$2:$F$40) -> Phòng QL KCN DVTS Đà Nẵng | F14: =_xlfn.XLOOKUP(B14,[1]DS!$B$2:$B$40,[1]DS!$G$2:$G$40) -> Trưởng phòng | G14: =_xlfn.XLOOKUP(B14,'Tổng hợp'!$B$4:$B$42,'Tổng hợp'!$AO$4:$AO$42,,0) -> 1023000
A15: =_xlfn.XLOOKUP(B15,[1]DS!$B$2:$B$40,[1]DS!$A$2:$A$40) -> 14 | B15: Trương Văn Hùng | C15: 1993 | D15: Nam | E15: =_xlfn.XLOOKUP(B15,[1]DS!$B$2:$B$40,[1]DS!$F$2:$F$40) -> Phòng QL KCN DVTS Đà Nẵng | F15: =_xlfn.XLOOKUP(B15,[1]DS!$B$2:$B$40,[1]DS!$G$2:$G$40) -> Cán sự | G15: =_xlfn.XLOOKUP(B15,'Tổng hợp'!$B$4:$B$42,'Tổng hợp'!$AO$4:$AO$42,,0) -> 1023000
A16: =_xlfn.XLOOKUP(B16,[1]DS!$B$2:$B$40,[1]DS!$A$2:$A$40) -> 15 | B16: Đỗ Viết Tấn | C16: 1973 | D16: Nam | E16: =_xlfn.XLOOKUP(B16,[1]DS!$B$2:$B$40,[1]DS!$F$2:$F$40) -> Phòng QL KCN DVTS Đà Nẵng | F16: =_xlfn.XLOOKUP(B16,[1]DS!$B$2:$B$40,[1]DS!$G$2:$G$40) -> Nhân viên bảo vệ | G16: =_xlfn.XLOOKUP(B16,'Tổng hợp'!$B$4:$B$42,'Tổng hợp'!$AO$4:$AO$42,,0) -> 921000
A17: =_xlfn.XLOOKUP(B17,[1]DS!$B$2:$B$40,[1]DS!$A$2:$A$40) -> 16 | B17: Phan Trung Tiến | C17: 1973 | D17: Nam | E17: =_xlfn.XLOOKUP(B17,[1]DS!$B$2:$B$40,[1]DS!$F$2:$F$40) -> Phòng QL KCN DVTS Đà Nẵng | F17: =_xlfn.XLOOKUP(B17,[1]DS!$B$2:$B$40,[1]DS!$G$2:$G$40) -> Nhân viên bảo vệ | G17: =_xlfn.XLOOKUP(B17,'Tổng hợp'!$B$4:$B$42,'Tổng hợp'!$AO$4:$AO$42,,0) -> 1023000
A18: =_xlfn.XLOOKUP(B18,[1]DS!$B$2:$B$40,[1]DS!$A$2:$A$40) -> 17 | B18: Lê Trung Hiếu | C18: 2001 | D18: Nam | E18: =_xlfn.XLOOKUP(B18,[1]DS!$B$2:$B$40,[1]DS!$F$2:$F$40) -> Phòng QL KCN DVTS Đà Nẵng | F18: =_xlfn.XLOOKUP(B18,[1]DS!$B$2:$B$40,[1]DS!$G$2:$G$40) -> Nhân viên bảo vệ | G18: =_xlfn.XLOOKUP(B18,'Tổng hợp'!$B$4:$B$42,'Tổng hợp'!$AO$4:$AO$42,,0) -> 1023000
A19: =_xlfn.XLOOKUP(B19,[1]DS!$B$2:$B$40,[1]DS!$A$2:$A$40) -> 18 | B19: Văn Quang Viên | C19: 1979 | D19: Nam | E19: =_xlfn.XLOOKUP(B19,[1]DS!$B$2:$B$40,[1]DS!$F$2:$F$40) -> Xí nghiệp QL&DV KCN Hòa Khánh | F19: =_xlfn.XLOOKUP(B19,[1]DS!$B$2:$B$40,[1]DS!$G$2:$G$40) -> Giám đốc XN | G19: =_xlfn.XLOOKUP(B19,'Tổng hợp'!$B$4:$B$42,'Tổng hợp'!$AO$4:$AO$42,,0) -> 1023000
A20: =_xlfn.XLOOKUP(B20,[1]DS!$B$2:$B$40,[1]DS!$A$2:$A$40) -> 19 | B20: Ngô Tấn Trung | C20: 1977 | D20: Nam | E20: =_xlfn.XLOOKUP(B20,[1]DS!$B$2:$B$40,[1]DS!$F$2:$F$40) -> Xí nghiệp QL&DV KCN Hòa Khánh | F20: =_xlfn.XLOOKUP(B20,[1]DS!$B$2:$B$40,[1]DS!$G$2:$G$40) -> Phó giám đốc XN | G20: =_xlfn.XLOOKUP(B20,'Tổng hợp'!$B$4:$B$42,'Tổng hợp'!$AO$4:$AO$42,,0) -> 1023000
A21: =_xlfn.XLOOKUP(B21,[1]DS!$B$2:$B$40,[1]DS!$A$2:$A$40) -> 20 | B21: Nguyễn Pho | C21: 1977 | D21: Nam | E21: =_xlfn.XLOOKUP(B21,[1]DS!$B$2:$B$40,[1]DS!$F$2:$F$40) -> Xí nghiệp QL&DV KCN Hòa Khánh | F21: =_xlfn.XLOOKUP(B21,[1]DS!$B$2:$B$40,[1]DS!$G$2:$G$40) -> Phó giám đốc XN | G21: =_xlfn.XLOOKUP(B21,'Tổng hợp'!$B$4:$B$42,'Tổng hợp'!$AO$4:$AO$42,,0) -> 1023000
A22: =_xlfn.XLOOKUP(B22,[1]DS!$B$2:$B$40,[1]DS!$A$2:$A$40) -> 21 | B22: Phan Văn Hùng | C22: 1972 | D22: Nam | E22: =_xlfn.XLOOKUP(B22,[1]DS!$B$2:$B$40,[1]DS!$F$2:$F$40) -> Xí nghiệp QL&DV KCN Hòa Khánh | F22: =_xlfn.XLOOKUP(B22,[1]DS!$B$2:$B$40,[1]DS!$G$2:$G$40) -> Cán sự | G22: =_xlfn.XLOOKUP(B22,'Tổng hợp'!$B$4:$B$42,'Tổng hợp'!$AO$4:$AO$42,,0) -> 1023000
A23: =_xlfn.XLOOKUP(B23,[1]DS!$B$2:$B$40,[1]DS!$A$2:$A$40) -> 22 | B23: Trần Văn Quân | C23: 1971 | D23: Nam | E23: =_xlfn.XLOOKUP(B23,[1]DS!$B$2:$B$40,[1]DS!$F$2:$F$40) -> Xí nghiệp QL&DV KCN Hòa Khánh | F23: =_xlfn.XLOOKUP(B23,[1]DS!$B$2:$B$40,[1]DS!$G$2:$G$40) -> Nhân viên bảo vệ | G23: =_xlfn.XLOOKUP(B23,'Tổng hợp'!$B$4:$B$42,'Tổng hợp'!$AO$4:$AO$42,,0) -> 1023000
A24: =_xlfn.XLOOKUP(B24,[1]DS!$B$2:$B$40,[1]DS!$A$2:$A$40) -> 23 | B24: Phan Xuân Khánh | C24: 1968 | D24: Nam | E24: =_xlfn.XLOOKUP(B24,[1]DS!$B$2:$B$40,[1]DS!$F$2:$F$40) -> Xí nghiệp QL&DV KCN Hòa Khánh | F24: =_xlfn.XLOOKUP(B24,[1]DS!$B$2:$B$40,[1]DS!$G$2:$G$40) -> Nhân viên lái xe | G24: =_xlfn.XLOOKUP(B24,'Tổng hợp'!$B$4:$B$42,'Tổng hợp'!$AO$4:$AO$42,,0) -> 1439000
A25: =_xlfn.XLOOKUP(B25,[1]DS!$B$2:$B$40,[1]DS!$A$2:$A$40) -> 24 | B25: Trương Công Tuấn | C25: 1993 | D25: Nam | E25: =_xlfn.XLOOKUP(B25,[1]DS!$B$2:$B$40,[1]DS!$F$2:$F$40) -> Xí nghiệp QL&DV KCN Hòa Khánh | F25: =_xlfn.XLOOKUP(B25,[1]DS!$B$2:$B$40,[1]DS!$G$2:$G$40) -> Nhân viên lái xe | G25: =_xlfn.XLOOKUP(B25,'Tổng hợp'!$B$4:$B$42,'Tổng hợp'!$AO$4:$AO$42,,0) -> 1439000
A26: =_xlfn.XLOOKUP(B26,[1]DS!$B$2:$B$40,[1]DS!$A$2:$A$40) -> 25 | B26: Nguyễn Phan Thanh | C26: 1987 | D26: Nam | E26: =_xlfn.XLOOKUP(B26,[1]DS!$B$2:$B$40,[1]DS!$F$2:$F$40) -> Xí nghiệp QL&DV KCN Hòa Khánh | F26: =_xlfn.XLOOKUP(B26,[1]DS!$B$2:$B$40,[1]DS!$G$2:$G$40) -> Nhân viên bảo vệ | G26: =_xlfn.XLOOKUP(B26,'Tổng hợp'!$B$4:$B$42,'Tổng hợp'!$AO$4:$AO$42,,0) -> 1023000
A27: =_xlfn.XLOOKUP(B27,[1]DS!$B$2:$B$40,[1]DS!$A$2:$A$40) -> 26 | B27: Phan Văn Tuấn | C27: 1977 | D27: Nam | E27: =_xlfn.XLOOKUP(B27,[1]DS!$B$2:$B$40,[1]DS!$F$2:$F$40) -> Xí nghiệp QL&DV KCN Hòa Khánh | F27: =_xlfn.XLOOKUP(B27,[1]DS!$B$2:$B$40,[1]DS!$G$2:$G$40) -> Nhân viên bảo vệ | G27: =_xlfn.XLOOKUP(B27,'Tổng hợp'!$B$4:$B$42,'Tổng hợp'!$AO$4:$AO$42,,0) -> 1023000
A28: =_xlfn.XLOOKUP(B28,[1]DS!$B$2:$B$40,[1]DS!$A$2:$A$40) -> 27 | B28: Võ Tòng Vũ | C28: 1999 | D28: Nam | E28: =_xlfn.XLOOKUP(B28,[1]DS!$B$2:$B$40,[1]DS!$F$2:$F$40) -> Xí nghiệp QL&DV KCN Hòa Khánh | F28: =_xlfn.XLOOKUP(B28,[1]DS!$B$2:$B$40,[1]DS!$G$2:$G$40) -> Nhân viên bảo vệ | G28: =_xlfn.XLOOKUP(B28,'Tổng hợp'!$B$4:$B$42,'Tổng hợp'!$AO$4:$AO$42,,0) -> 1023000
A29: =_xlfn.XLOOKUP(B29,[1]DS!$B$2:$B$40,[1]DS!$A$2:$A$40) -> 28 | B29: Nguyễn Trung Kiên | C29: 2001 | D29: Nam | E29: =_xlfn.XLOOKUP(B29,[1]DS!$B$2:$B$40,[1]DS!$F$2:$F$40) -> Xí nghiệp QL&DV KCN Hòa Khánh | F29: =_xlfn.XLOOKUP(B29,[1]DS!$B$2:$B$40,[1]DS!$G$2:$G$40) -> Nhân viên bảo vệ | G29: =_xlfn.XLOOKUP(B29,'Tổng hợp'!$B$4:$B$42,'Tổng hợp'!$AO$4:$AO$42,,0) -> 1023000
A30: =_xlfn.XLOOKUP(B30,[1]DS!$B$2:$B$40,[1]DS!$A$2:$A$40) -> 29 | B30: Trần Thu Hương | C30: 1974 | D30: Nữ | E30: =_xlfn.XLOOKUP(B30,[1]DS!$B$2:$B$40,[1]DS!$F$2:$F$40) -> Lãnh đạo | F30: =_xlfn.XLOOKUP(B30,[1]DS!$B$2:$B$40,[1]DS!$G$2:$G$40) -> Phó giám đốc | G30: =_xlfn.XLOOKUP(B30,'Tổng hợp'!$B$4:$B$42,'Tổng hợp'!$AO$4:$AO$42,,0) -> 1023000
A31: =_xlfn.XLOOKUP(B31,[1]DS!$B$2:$B$40,[1]DS!$A$2:$A$40) -> 30 | B31: Nguyễn Thị Thơ | C31: 1976 | D31: Nữ | E31: =_xlfn.XLOOKUP(B31,[1]DS!$B$2:$B$40,[1]DS!$F$2:$F$40) -> Phòng Hành chính-Tổng hợp | F31: =_xlfn.XLOOKUP(B31,[1]DS!$B$2:$B$40,[1]DS!$G$2:$G$40) -> Phó trưởng phòng | G31: =_xlfn.XLOOKUP(B31,'Tổng hợp'!$B$4:$B$42,'Tổng hợp'!$AO$4:$AO$42,,0) -> 1023000
A32: =_xlfn.XLOOKUP(B32,[1]DS!$B$2:$B$40,[1]DS!$A$2:$A$40) -> 31 | B32: Phạm Gia Hy | C32: 1996 | D32: Nữ | E32: =_xlfn.XLOOKUP(B32,[1]DS!$B$2:$B$40,[1]DS!$F$2:$F$40) -> Phòng Hành chính-Tổng hợp | F32: =_xlfn.XLOOKUP(B32,[1]DS!$B$2:$B$40,[1]DS!$G$2:$G$40) -> Văn thư viên | G32: =_xlfn.XLOOKUP(B32,'Tổng hợp'!$B$4:$B$42,'Tổng hợp'!$AO$4:$AO$42,,0) -> 1023000
A33: =_xlfn.XLOOKUP(B33,[1]DS!$B$2:$B$40,[1]DS!$A$2:$A$40) -> 32 | B33: Đinh Thị Kim Tâm | C33: 1988 | D33: Nữ | E33: =_xlfn.XLOOKUP(B33,[1]DS!$B$2:$B$40,[1]DS!$F$2:$F$40) -> Phòng Kế hoạch | F33: =_xlfn.XLOOKUP(B33,[1]DS!$B$2:$B$40,[1]DS!$G$2:$G$40) -> Chuyên viên | G33: =_xlfn.XLOOKUP(B33,'Tổng hợp'!$B$4:$B$42,'Tổng hợp'!$AO$4:$AO$42,,0) -> 1023000
A34: =_xlfn.XLOOKUP(B34,[1]DS!$B$2:$B$40,[1]DS!$A$2:$A$40) -> 33 | B34: Nguyễn Thị Hoa | C34: 1975 | D34: Nữ | E34: =_xlfn.XLOOKUP(B34,[1]DS!$B$2:$B$40,[1]DS!$F$2:$F$40) -> Phòng Kế toán - Tài vụ | F34: =_xlfn.XLOOKUP(B34,[1]DS!$B$2:$B$40,[1]DS!$G$2:$G$40) -> Trưởng phòng | G34: =_xlfn.XLOOKUP(B34,'Tổng hợp'!$B$4:$B$42,'Tổng hợp'!$AO$4:$AO$42,,0) -> 1023000
A35: =_xlfn.XLOOKUP(B35,[1]DS!$B$2:$B$40,[1]DS!$A$2:$A$40) -> 34 | B35: Nguyễn Hạnh Thắm | C35: 1987 | D35: Nữ | E35: =_xlfn.XLOOKUP(B35,[1]DS!$B$2:$B$40,[1]DS!$F$2:$F$40) -> Phòng Kế toán - Tài vụ | F35: =_xlfn.XLOOKUP(B35,[1]DS!$B$2:$B$40,[1]DS!$G$2:$G$40) -> Phó trưởng phòng | G35: =_xlfn.XLOOKUP(B35,'Tổng hợp'!$B$4:$B$42,'Tổng hợp'!$AO$4:$AO$42,,0) -> 1023000
A36: =_xlfn.XLOOKUP(B36,[1]DS!$B$2:$B$40,[1]DS!$A$2:$A$40) -> 35 | B36: Nguyễn Thị Hằng Nga | C36: 1988 | D36: Nữ | E36: =_xlfn.XLOOKUP(B36,[1]DS!$B$2:$B$40,[1]DS!$F$2:$F$40) -> Phòng Kế toán - Tài vụ | F36: =_xlfn.XLOOKUP(B36,[1]DS!$B$2:$B$40,[1]DS!$G$2:$G$40) -> Chuyên viên | G36: =_xlfn.XLOOKUP(B36,'Tổng hợp'!$B$4:$B$42,'Tổng hợp'!$AO$4:$AO$42,,0) -> 1023000
A37: =_xlfn.XLOOKUP(B37,[1]DS!$B$2:$B$40,[1]DS!$A$2:$A$40) -> 36 | B37: Phạm Thị Cẩm Lai | C37: 1989 | D37: Nữ | E37: =_xlfn.XLOOKUP(B37,[1]DS!$B$2:$B$40,[1]DS!$F$2:$F$40) -> Phòng Kế toán - Tài vụ | F37: =_xlfn.XLOOKUP(B37,[1]DS!$B$2:$B$40,[1]DS!$G$2:$G$40) -> Chuyên viên | G37: =_xlfn.XLOOKUP(B37,'Tổng hợp'!$B$4:$B$42,'Tổng hợp'!$AO$4:$AO$42,,0) -> 1023000
A38: =_xlfn.XLOOKUP(B38,[1]DS!$B$2:$B$40,[1]DS!$A$2:$A$40) -> 37 | B38: Trần Thị Anh Thư | C38: 1984 | D38: Nữ | E38: =_xlfn.XLOOKUP(B38,[1]DS!$B$2:$B$40,[1]DS!$F$2:$F$40) -> Phòng Kế hoạch | F38: =_xlfn.XLOOKUP(B38,[1]DS!$B$2:$B$40,[1]DS!$G$2:$G$40) -> Phó phòng | G38: =_xlfn.XLOOKUP(B38,'Tổng hợp'!$B$4:$B$42,'Tổng hợp'!$AO$4:$AO$42,,0) -> 921000
A39: =_xlfn.XLOOKUP(B39,[1]DS!$B$2:$B$40,[1]DS!$A$2:$A$40) -> 38 | B39: Hồ Thị Vân | C39: 1975 | D39: Nữ | E39: =_xlfn.XLOOKUP(B39,[1]DS!$B$2:$B$40,[1]DS!$F$2:$F$40) -> Phòng QL KCN DVTS Đà Nẵng | F39: =_xlfn.XLOOKUP(B39,[1]DS!$B$2:$B$40,[1]DS!$G$2:$G$40) -> Chuyên viên | G39: =_xlfn.XLOOKUP(B39,'Tổng hợp'!$B$4:$B$42,'Tổng hợp'!$AO$4:$AO$42,,0) -> 1023000
A40: =_xlfn.XLOOKUP(B40,[1]DS!$B$2:$B$40,[1]DS!$A$2:$A$40) -> 39 | B40: Nguyễn Thị Thu | C40: 1974 | D40: Nữ | E40: =_xlfn.XLOOKUP(B40,[1]DS!$B$2:$B$40,[1]DS!$F$2:$F$40) -> Xí nghiệp QL&DV KCN Hòa Khánh | F40: =_xlfn.XLOOKUP(B40,[1]DS!$B$2:$B$40,[1]DS!$G$2:$G$40) -> Phục vụ | G40: =_xlfn.XLOOKUP(B40,'Tổng hợp'!$B$4:$B$42,'Tổng hợp'!$AO$4:$AO$42,,0) -> 1023000
...
